Workbook

Sheet Rodada 1 de Venda
B1: Preço Médio da Cesta | C1: Disponibilidade | D1: CSAT | E1: % Part. Demanda de Vendas | G1: Preço | H1: Disp | I1: CSAT | J1: Total | M1: Preço Médio da Cesta | N1: Disponibilidade | O1: Serviços | P1: Pontuação
A2: Bretas | B2: =Bretas!J11 -> 868.97314 | C2: =Bretas!J10 -> 0.25 | D2: =Bretas!J5 -> 0.8 | E2: =ROUND(J2/$J$6,3) -> 0.414 | G2: =IFERROR(_xlfn.XLOOKUP(B2,M:M,P:P),IF(B2>$M$4,2,3)) -> 4 | H2: =IFERROR(_xlfn.XLOOKUP(C2,N:N,P:P),IF(C2>$N$4,2,3)) -> 4 | I2: =IFERROR(_xlfn.XLOOKUP(D2,O:O,P:P),IF(D2>$O$4,2,3)) -> 4 | J2: =SUM(G2:I2) -> 12 | L2: Melhor | M2: =SMALL(B2:B5,1) -> 868.97314 | N2: =LARGE(C2:C5,1) -> 0.25 | O2: =LARGE(D2:D5,1) -> 0.8 | P2: 4
A3: GBarbosa | B3: =GBarbosa!J11 -> 992.90028 | C3: =GBarbosa!J10 -> 0.24713376 | D3: =GBarbosa!J5 -> 0.42 | E3: =ROUND(J3/$J$6,3) -> 0.207 | G3: =IFERROR(_xlfn.XLOOKUP(B3,M:M,P:P),IF(B3>$M$4,2,3)) -> 1 | H3: =IFERROR(_xlfn.XLOOKUP(C3,N:N,P:P),IF(C3>$N$4,2,3)) -> 2 | I3: =IFERROR(_xlfn.XLOOKUP(D3,O:O,P:P),IF(D3>$O$4,2,3)) -> 3 | J3: =SUM(G3:I3) -> 6 | L3: Pior | M3: =LARGE(B2:B5,1) -> 992.90028 | N3: =SMALL(C2:C5,1) -> 0.2 | O3: =SMALL(D2:D5,1) -> 0.2 | P3: 1
A4: Prezunic | B4: =Prezunic!J11 -> 991.77266 | C4: =Prezunic!J10 -> 0.2 | D4: =Prezunic!J5 -> 0.2 | E4: =ROUND(J4/$J$6,3) -> 0.138 | G4: =IFERROR(_xlfn.XLOOKUP(B4,M:M,P:P),IF(B4>$M$4,2,3)) -> 2 | H4: =IFERROR(_xlfn.XLOOKUP(C4,N:N,P:P),IF(C4>$N$4,2,3)) -> 1 | I4: =IFERROR(_xlfn.XLOOKUP(D4,O:O,P:P),IF(D4>$O$4,2,3)) -> 1 | J4: =SUM(G4:I4) -> 4 | L4: Média | M4: =AVERAGE(B2:B5) -> 952.97553 | N4: =AVERAGE(C2:C5) -> 0.23670382 | O4: =AVERAGE(D2:D5) -> 0.43
A5: Giga | B5: =Giga!J11 -> 958.25604 | C5: =Giga!J10 -> 0.24968153 | D5: =Giga!J5 -> 0.3 | E5: =ROUND(J5/$J$6,3) -> 0.241 | G5: =IFERROR(_xlfn.XLOOKUP(B5,M:M,P:P),IF(B5>$M$4,2,3)) -> 2 | H5: =IFERROR(_xlfn.XLOOKUP(C5,N:N,P:P),IF(C5>$N$4,2,3)) -> 2 | I5: =IFERROR(_xlfn.XLOOKUP(D5,O:O,P:P),IF(D5>$O$4,2,3)) -> 3 | J5: =SUM(G5:I5) -> 7
J6: =SUM(J2:J5) -> 29
A7: 1ª Rodada de Vendas
A8: Vendas | B8: Perecíves | C8: Mercearia | D8: Eletro | E8: Hipel | F8: Total
A9: Rodada 1 | B9: ='Dados de apoio'!H13 -> 2000 | C9: ='Dados de apoio'!I13 -> 3000 | D9: ='Dados de apoio'!J13 -> 350 | E9: ='Dados de apoio'!K13 -> 2500 | F9: =SUM(B9:E9) -> 7850
A11: Bretas | B11: =ROUND(B$9*$E2,0) -> 828 | C11: =ROUND(C$9*$E2,0) -> 1242 | D11: =ROUND(D$9*$E2,0) -> 145 | E11: =ROUND(E$9*$E2,0) -> 1035 | F11: =SUM(B11:E11) -> 3250 | G11: =$A$9&A11 -> Rodada 1Bretas
A12: GBarbosa | B12: =ROUND($B$9*E3,0) -> 414 | C12: =ROUND(C$9*$E3,0) -> 621 | D12: =ROUND(D$9*$E3,0) -> 72 | E12: =ROUND(E$9*$E3,0) -> 518 | F12: =SUM(B12:E12) -> 1625 | G12: =$A$9&A12 -> Rodada 1GBarbosa
A13: Prezunic | B13: =ROUND($B$9*E4,0) -> 276 | C13: =ROUND(C$9*$E4,0) -> 414 | D13: =ROUND(D$9*$E4,0) -> 48 | E13: =ROUND(E$9*$E4,0) -> 345 | F13: =SUM(B13:E13) -> 1083 | G13: =$A$9&A13 -> Rodada 1Prezunic
A14: Giga | B14: =ROUND($B$9*$E$5,0) -> 482 | C14: =ROUND($C$9*$E$5,0) -> 723 | D14: =ROUND(D$9*$E5,0) -> 84 | E14: =ROUND(E$9*$E5,0) -> 603 | F14: =SUM(B14:E14) -> 1892 | G14: =$A$9&A14 -> Rodada 1Giga

Sheet Demais Rodadas de Venda
B1: Preço Médio da Cesta | C1: Disponibilidade | D1: CSAT | E1: % Part. Demanda de Vendas | G1: Preço | H1: Disp | I1: CSAT | J1: Total | M1: Preço Médio da Cesta | N1: Disponibilidade | O1: Serviços | P1: Pontuação
A2: Bretas | B2: =Bretas!K11 -> 899.91641 | C2: =Bretas!K10 -> 0.37452229 | D2: =Bretas!J5 -> 0.8 | E2: =ROUND(J2/$J$6,3) -> 0.313 | G2: =IFERROR(_xlfn.XLOOKUP(B2,M:M,P:P),IF(B2>$M$4,2,3)) -> 3 | H2: =IFERROR(_xlfn.XLOOKUP(C2,N:N,P:P),IF(C2>$N$4,2,3)) -> 3 | I2: =IFERROR(_xlfn.XLOOKUP(D2,O:O,P:P),IF(D2>$O$4,2,3)) -> 4 | J2: =SUM(G2:I2) -> 10 | L2: Melhor | M2: =SMALL(B2:B5,1) -> 855.72849 | N2: =LARGE(C2:C5,1) -> 0.58305732 | O2: =LARGE(D2:D5,1) -> 0.8 | P2: 4
A3: GBarbosa | B3: =GBarbosa!K11 -> 985.63842 | C3: =GBarbosa!K10 -> 0.34484076 | D3: =GBarbosa!J5 -> 0.42 | E3: =ROUND(J3/$J$6,3) -> 0.219 | G3: =IFERROR(_xlfn.XLOOKUP(B3,M:M,P:P),IF(B3>$M$4,2,3)) -> 1 | H3: =IFERROR(_xlfn.XLOOKUP(C3,N:N,P:P),IF(C3>$N$4,2,3)) -> 3 | I3: =IFERROR(_xlfn.XLOOKUP(D3,O:O,P:P),IF(D3>$O$4,2,3)) -> 3 | J3: =SUM(G3:I3) -> 7 | L3: Pior | M3: =LARGE(B2:B5,1) -> 985.63842 | N3: =SMALL(C2:C5,1) -> 0.24968153 | O3: =SMALL(D2:D5,1) -> 0.2 | P3: 1
A4: Prezunic | B4: =Prezunic!K11 -> 855.72849 | C4: =Prezunic!K10 -> 0.58305732 | D4: =Prezunic!J5 -> 0.2 | E4: =ROUND(J4/$J$6,3) -> 0.281 | G4: =IFERROR(_xlfn.XLOOKUP(B4,M:M,P:P),IF(B4>$M$4,2,3)) -> 4 | H4: =IFERROR(_xlfn.XLOOKUP(C4,N:N,P:P),IF(C4>$N$4,2,3)) -> 4 | I4: =IFERROR(_xlfn.XLOOKUP(D4,O:O,P:P),IF(D4>$O$4,2,3)) -> 1 | J4: =SUM(G4:I4) -> 9 | L4: Média | M4: =AVERAGE(B2:B5) -> 916.55151 | N4: =AVERAGE(C2:C5) -> 0.38802548 | O4: =AVERAGE(D2:D5) -> 0.43
A5: Giga | B5: =Giga!K11 -> 924.92271 | C5: =Giga!J10 -> 0.24968153 | D5: =Giga!J5 -> 0.3 | E5: =ROUND(J5/$J$6,3) -> 0.188 | G5: =IFERROR(_xlfn.XLOOKUP(B5,M:M,P:P),IF(B5>$M$4,2,3)) -> 2 | H5: =IFERROR(_xlfn.XLOOKUP(C5,N:N,P:P),IF(C5>$N$4,2,3)) -> 1 | I5: =IFERROR(_xlfn.XLOOKUP(D5,O:O,P:P),IF(D5>$O$4,2,3)) -> 3 | J5: =SUM(G5:I5) -> 6
J6: =SUM(J2:J5) -> 32
A7: 2ª Rodada de Vendas
A8: Vendas | B8: Perecíves | C8: Mercearia | D8: Eletro | E8: Hipel | F8: Total
A9: Rodada 2 | B9: ='Dados de apoio'!H14 -> 800 | C9: ='Dados de apoio'!I14 -> 1200 | D9: ='Dados de apoio'!J14 -> 140 | E9: ='Dados de apoio'!K14 -> 1000 | F9: =SUM(B9:E9) -> 3140
A11: Bretas | B11: =ROUND(B$9*$E2,0) -> 250 | C11: =ROUND(C$9*$E2,0) -> 376 | D11: =ROUND(D$9*$E2,0) -> 44 | E11: =ROUND(E$9*$E2,0) -> 313 | F11: =SUM(B11:E11) -> 983 | G11: =$A$9&A11 -> Rodada 2Bretas
A12: GBarbosa | B12: =ROUND($B$9*E3,0) -> 175 | C12: =ROUND(C$9*$E3,0) -> 263 | D12: =ROUND(D$9*$E3,0) -> 31 | E12: =ROUND(E$9*$E3,0) -> 219 | F12: =SUM(B12:E12) -> 688 | G12: =$A$9&A12 -> Rodada 2GBarbosa
A13: Prezunic | B13: =ROUND($B$9*E4,0) -> 225 | C13: =ROUND(C$9*$E4,0) -> 337 | D13: =ROUND(D$9*$E4,0) -> 39 | E13: =ROUND(E$9*$E4,0) -> 281 | F13: =SUM(B13:E13) -> 882 | G13: =$A$9&A13 -> Rodada 2Prezunic
A14: Giga | B14: =B9-SUM(B11:B13) -> 150 | C14: =C9-SUM(C11:C13) -> 224 | D14: =D9-SUM(D11:D13) -> 26 | E14: =E9-SUM(E11:E13) -> 187 | F14: =SUM(B14:E14) -> 587 | G14: =$A$9&A14 -> Rodada 2Giga
A16: Vendas | B16: Perecíves | C16: Mercearia | D16: Eletro | E16: Hipel | F16: Total
A17: Venda Atacado | B17: ='Dados de apoio'!H19 -> 400 | C17: ='Dados de apoio'!I19 -> 600 | D17: ='Dados de apoio'!J19 -> 70 | E17: ='Dados de apoio'!K19 -> 500 | F17: =SUM(B17:E17) -> 1570
A19: Bretas | B19: 320 | F19: =SUM(B19:E19) -> 320 | G19: =$A$17&A19 -> Venda AtacadoBretas
A20: GBarbosa | C20: 400 | E20: 500 | F20: =SUM(B20:E20) -> 900 | G20: =$A$17&A20 -> Venda AtacadoGBarbosa
A21: Prezunic | F21: =SUM(B21:E21) -> 0 | G21: =$A$17&A21 -> Venda AtacadoPrezunic
A22: Giga | B22: 400 | C22: 200 | D22: 70 | F22: =SUM(B22:E22) -> 670 | G22: =$A$17&A22 -> Venda AtacadoGiga
A23: Total Vendido | B23: =SUM(B19:B21) -> 320 | C23: =SUM(C19:C22) -> 600 | D23: =SUM(D19:D21) -> 0 | E23: =SUM(E19:E21) -> 500 | F23: =SUM(B23:E23) -> 1420
A25: Vendas | B25: Perecíves | C25: Mercearia | D25: Eletro | E25: Hipel | F25: Total
A26: Preço Atacado
A27: Bretas | B27: 10 | C27: 10 | D27: 10 | E27: 10 | G27: =$A$26&A27 -> Preço AtacadoBretas
A28: GBarbosa | B28: =B27*2 -> 20 | C28: =C27*2 -> 20 | D28: =D27*2 -> 20 | E28: =E27*2 -> 20 | G28: =$A$26&A28 -> Preço AtacadoGBarbosa
A29: Prezunic | B29: =B28*2 -> 40 | C29: =C28*2 -> 40 | D29: =D28*2 -> 40 | E29: =E28*2 -> 40 | G29: =$A$26&A29 -> Preço AtacadoPrezunic
A30: Giga | B30: =B29*2 -> 80 | C30: =C29*2 -> 80 | D30: =D29*2 -> 80 | E30: =E29*2 -> 80 | G30: =$A$26&A30 -> Preço AtacadoGiga
A32: 3ª Rodada de Vendas
A33: Vendas | B33: Perecíves | C33: Mercearia | D33: Eletro | E33: Hipel | F33: Total
A34: Rodada 3 | B34: ='Dados de apoio'!H15 -> 1200 | C34: ='Dados de apoio'!I15 -> 1800 | D34: ='Dados de apoio'!J15 -> 210 | E34: ='Dados de apoio'!K15 -> 1500 | F34: =SUM(B34:E34) -> 4710
A36: Bretas | B36: =ROUND(B$34*$E2,0) -> 376 | C36: =ROUND(C$34*$E2,0) -> 563 | D36: =ROUND(D$34*$E2,0) -> 66 | E36: =ROUND(E$34*$E2,0) -> 470 | F36: =SUM(B36:E36) -> 1475 | G36: =$A$34&A36 -> Rodada 3Bretas
A37: GBarbosa | B37: =ROUND(B$34*$E3,0) -> 263 | C37: =ROUND(C$34*$E3,0) -> 394 | D37: =ROUND(D$34*$E3,0) -> 46 | E37: =ROUND(E$34*$E3,0) -> 329 | F37: =SUM(B37:E37) -> 1032 | G37: =$A$34&A37 -> Rodada 3GBarbosa
A38: Prezunic | B38: =ROUND(B$34*$E4,0) -> 337 | C38: =ROUND(C$34*$E4,0) -> 506 | D38: =ROUND(D$34*$E4,0) -> 59 | E38: =ROUND(E$34*$E4,0) -> 422 | F38: =SUM(B38:E38) -> 1324 | G38: =$A$34&A38 -> Rodada 3Prezunic
A39: Giga | B39: =B34-SUM(B36:B38) -> 224 | C39: =C34-SUM(C36:C38) -> 337 | D39: =D34-SUM(D36:D38) -> 39 | E39: =E34-SUM(E36:E38) -> 279 | F39: =SUM(B39:E39) -> 879 | G39: =$A$34&A39 -> Rodada 3Giga

Sheet Bretas
A1: Bretas | B1: Perecíves | C1: Mercearia | D1: Eletro | E1: Hipel | F1: Total | I1: Quant. Operadores Caixa | J1: 10 | M1: Caixa | N1: ='Dados de apoio'!B21 -> 700000
I2: Quant. Operadores Serviço | J2: 5 | M2: Estoque | N2: =-(F5+F23) -> -334120
A3: Qtd Estoque | B3: 1000 | C3: 1500 | D3: 175 | E3: 1250 | F3: =SUM(B3:E3) -> 3925 | I3: Resultado Testes | J3: 0.8 | M3: CAPEX | N3: =-L20 -> -320000
A4: Custo Unit | B4: ='Dados de apoio'!H3 -> 20 | C4: ='Dados de apoio'!I3 -> 30 | D4: ='Dados de apoio'!J3 -> 500 | E4: ='Dados de apoio'!K3 -> 45 | I4: SLA Serviços | J4: =IF(J2="",6,IFERROR(_xlfn.XLOOKUP(J2,'Dados de apoio'!O:O,'Dados de apoio'!P:P),5)) -> 1 | M4: Saldo | N4: =SUM(N1:N3) -> 45880
A5: Total Estoque | B5: =B3*B4 -> 20000 | C5: =C3*C4 -> 45000 | D5: =D3*D4 -> 87500 | E5: =E3*E4 -> 56250 | F5: =SUM(B5:E5) -> 208750 | I5: CSAT | J5: =J3*(J1/'Dados de apoio'!R4) -> 0.8 | N5: =IF(N4<0,"Revisar Caixa","Caixa OK") -> Caixa OK
A7: MIX Disponível | B7: ='Dados de apoio'!H4 -> 4000 | C7: ='Dados de apoio'!I4 -> 6000 | D7: ='Dados de apoio'!J4 -> 700 | E7: ='Dados de apoio'!K4 -> 5000 | F7: =SUM(B7:E7) -> 15700
A8: Disponibilidade | B8: =B3/B7 -> 0.25 | C8: =C3/C7 -> 0.25 | D8: =D3/D7 -> 0.25 | E8: =E3/E7 -> 0.25 | F8: =F3/F7 -> 0.25
J9: 1ª Conf. | K9: 2ª Conf.
I10: Disponibiliidade | J10: =F8 -> 0.25 | K10: =F26 -> 0.37452229
A11: % Margem | B11: 0.12 | C11: 0.12 | D11: 0.12 | E11: 0.12 | I11: Preço da Cesta | J11: =SUM(B14:E14) -> 868.97314 | K11: =SUM(B31:E31) -> 899.91641
A12: % Impostos | B12: ='Dados de apoio'!H5 -> 0.12 | C12: ='Dados de apoio'!I5 -> 0.07 | D12: ='Dados de apoio'!J5 -> 0.25 | E12: ='Dados de apoio'!K5 -> 0.17
J13: Aprovado? | K13: Aprovado? | L13: R$
A14: Preço de Venda | B14: =(B4/(100%-B12))*(100%+B11) -> 25.454545 | C14: =(C4/(100%-C12))*(100%+C11) -> 36.129032 | D14: =(D4/(100%-D12))*(100%+D11) -> 746.66667 | E14: =(E4/(100%-E12))*(100%+E11) -> 60.722892 | I14: CAPEX Segurança | J14: Sim | K14: =J14 -> Sim | L14: =IF(K14="Sim",_xlfn.XLOOKUP(I14,'Dados de apoio'!A:A,'Dados de apoio'!C:C),0) -> 50000
I15: CAPEX Balança/Freezer | J15: Não | K15: =J15 -> Não | L15: =IF(K15="Sim",_xlfn.XLOOKUP(I15,'Dados de apoio'!A:A,'Dados de apoio'!C:C),0) -> 0
I16: CAPEX Redes | J16: Sim | K16: =J16 -> Sim | L16: =IF(K16="Sim",_xlfn.XLOOKUP(I16,'Dados de apoio'!A:A,'Dados de apoio'!C:C),0) -> 80000
I17: CAPEX Site | J17: Sim | K17: =J17 -> Sim | L17: =IF(K17="Sim",_xlfn.XLOOKUP(I17,'Dados de apoio'!A:A,'Dados de apoio'!C:C),0) -> 65000
A18: --------------------------------- | I18: CAPEX Self Checkout | J18: Sim | K18: =J18 -> Sim | L18: =IF(K18="Sim",_xlfn.XLOOKUP(I18,'Dados de apoio'!A:A,'Dados de apoio'!C:C),0) -> 80000
A19: 2ª Rodada de configuração | I19: CAPEX Melhoria Contínua | J19: Sim | K19: =J19 -> Sim | L19: =IF(K19="Sim",_xlfn.XLOOKUP(I19,'Dados de apoio'!A:A,'Dados de apoio'!C:C),0) -> 45000
A20: Bretas | B20: Perecíves | C20: Mercearia | D20: Eletro | E20: Hipel | F20: Total | J20: Total CAPEX | L20: =SUM(L14:L19) -> 320000
A21: Estoque Atual | B21: =B44 -> 227 | C21: =C44 -> 258 | D21: =D44 -> 30 | E21: =E44 -> 215 | F21: =SUM(B21:E21) -> 730
A22: Qtd A comprar | B22: 400 | C22: 942 | D22: 110 | E22: 758 | F22: =SUM(B22:E22) -> 2210
A23: R$ Total Comprado | B23: =B22*B4 -> 8000 | C23: =C22*C4 -> 28260 | D23: =D22*D4 -> 55000 | E23: =E22*E4 -> 34110 | F23: =SUM(B23:E23) -> 125370
A24: Novo Estoque | B24: =B21+B22 -> 627 | C24: =C21+C22 -> 1200 | D24: =D21+D22 -> 140 | E24: =E21+E22 -> 973 | F24: =SUM(B24:E24) -> 2940 | I24: Licença Software | J24: QTd | K24: Valor CAPEX | L24: Valor CAPEX
I25: Sistema Operacional (por usuário) | J25: =J2 -> 5 | K25: ='Dados de apoio'!B12 -> 120 | L25: =K25*J25 -> 600
A26: Disponibilidade | B26: =B24/(B7-'Dados de apoio'!H13) -> 0.3135 | C26: =C24/(C7-'Dados de apoio'!I13) -> 0.4 | D26: =D24/(D7-'Dados de apoio'!J13) -> 0.4 | E26: =E24/(E7-'Dados de apoio'!K13) -> 0.3892 | F26: =F24/(F7-'Dados de apoio'!L13) -> 0.37452229 | I26: PDVs + Selfcheckout (Por Equipamento) | J26: =J1+IF(J18="Sim",4,0) -> 14 | K26: ='Dados de apoio'!B13 -> 80 | L26: =K26*J26 -> 1120
I27: Site (Valor único) | J27: 1 | K27: ='Dados de apoio'!B14*IF(K17="sim",1.3,1) -> 650 | L27: =K27*J27 -> 650
A28: % Margem | B28: 0.25 | C28: 0.25 | D28: 0.15 | E28: 0.19 | I28: Sistemas de segurança (Valor único) | J28: 1 | K28: ='Dados de apoio'!B15*IF(K14="sim",1.2,1) -> 600 | L28: =K28*J28 -> 600
A29: % Impostos | B29: ='Dados de apoio'!H5 -> 0.12 | C29: ='Dados de apoio'!I5 -> 0.07 | D29: ='Dados de apoio'!J5 -> 0.25 | E29: ='Dados de apoio'!K5 -> 0.17 | K29: Total | L29: =SUM(L25:L28) -> 2970
A31: Preço de Venda | B31: =(B4/(100%-B29))*(100%+B28) -> 28.409091 | C31: =(C4/(100%-C29))*(100%+C28) -> 40.322581 | D31: =(D4/(100%-D29))*(100%+D28) -> 766.66667 | E31: =(E4/(100%-E29))*(100%+E28) -> 64.518072
A35: 1ª Rodada de Vendas
A36: Rodada 1 | B36: =_xlfn.XLOOKUP($A36&$A$1,'Rodada 1 de Venda'!$G:$G,'Rodada 1 de Venda'!B:B) -> 828 | C36: =_xlfn.XLOOKUP($A36&$A1,'Rodada 1 de Venda'!$G:$G,'Rodada 1 de Venda'!C:C) -> 1242 | D36: =_xlfn.XLOOKUP($A36&$A1,'Rodada 1 de Venda'!$G:$G,'Rodada 1 de Venda'!D:D) -> 145 | E36: =_xlfn.XLOOKUP($A36&$A1,'Rodada 1 de Venda'!$G:$G,'Rodada 1 de Venda'!E:E) -> 1035 | F36: =SUM(B36:E36) -> 3250
A37: Incidente Segurança | B37: =-ROUND(IF($J$14="Sim",0,B36/30*($J$4+_xlfn.XLOOKUP($I$14,'Dados de apoio'!$A:$A,'Dados de apoio'!$B:$B))),0) -> 0 | C37: =-ROUND(IF($J$14="Sim",0,C36/30*($J$4+_xlfn.XLOOKUP($I$14,'Dados de apoio'!$A:$A,'Dados de apoio'!$B:$B))),0) -> 0 | D37: =-ROUND(IF($J$14="Sim",0,D36/30*($J$4+_xlfn.XLOOKUP($I$14,'Dados de apoio'!$A:$A,'Dados de apoio'!$B:$B))),0) -> 0 | E37: =-ROUND(IF($J$14="Sim",0,E36/30*($J$4+_xlfn.XLOOKUP($I$14,'Dados de apoio'!$A:$A,'Dados de apoio'!$B:$B))),0) -> 0 | F37: =SUM(B37:E37) -> 0
A38: Incidente Balanças/Freezer | B38: =-ROUND(IF($J$15="Sim",0,B36/30*($J$4+_xlfn.XLOOKUP($I$15,'Dados de apoio'!$A:$A,'Dados de apoio'!$B:$B))),0) -> -55 | C38: 0 | D38: 0 | E38: 0 | F38: =SUM(B38:E38) -> -55
A39: Devolução Venda | B39: =IF(SUM(B36:B38)>B3,B3-SUM(B36:B38),0) -> 0 | C39: =IF(SUM(C36:C38)>C3,C3-SUM(C36:C38),0) -> 0 | D39: =IF(SUM(D36:D38)>D3,D3-SUM(D36:D38),0) -> 0 | E39: =IF(SUM(E36:E38)>E3,E3-SUM(E36:E38),0) -> 0 | F39: =SUM(B39:E39) -> 0
A40: Total Vendido | B40: =SUM(B36:B39) -> 773 | C40: =SUM(C36:C39) -> 1242 | D40: =SUM(D36:D39) -> 145 | E40: =SUM(E36:E39) -> 1035 | F40: =SUM(F36:F39) -> 3195
A42: Valor de venda | B42: =B40*B$14 -> 19676.364 | C42: =C40*C$14 -> 44872.258 | D42: =D40*D$14 -> 108266.67 | E42: =E40*E$14 -> 62848.193 | F42: =SUM(B42:E42) -> 235663.48
A44: Estoque | B44: =B3-B40 -> 227 | C44: =C3-C40 -> 258 | D44: =D3-D40 -> 30 | E44: =E3-E40 -> 215
A46: 2ª Rodada de Vendas
A47: Rodada 2 | B47: =_xlfn.XLOOKUP($A47&$A$1,'Demais Rodadas de Venda'!$G:$G,'Demais Rodadas de Venda'!B:B) -> 250 | C47: =_xlfn.XLOOKUP($A47&$A$1,'Demais Rodadas de Venda'!$G:$G,'Demais Rodadas de Venda'!C:C) -> 376 | D47: =_xlfn.XLOOKUP($A47&$A$1,'Demais Rodadas de Venda'!$G:$G,'Demais Rodadas de Venda'!D:D) -> 44 | E47: =_xlfn.XLOOKUP($A47&$A$1,'Demais Rodadas de Venda'!$G:$G,'Demais Rodadas de Venda'!E:E) -> 313 | F47: =SUM(B47:E47) -> 983
A48: Incidente Cartões | B48: =-ROUND(IF($J$16="Sim",0,B47/30*($J$4+_xlfn.XLOOKUP($I$16,'Dados de apoio'!$A:$A,'Dados de apoio'!$B:$B))),0) -> 0 | C48: =-ROUND(IF($J$16="Sim",0,C47/30*($J$4+_xlfn.XLOOKUP($I$16,'Dados de apoio'!$A:$A,'Dados de apoio'!$B:$B))),0) -> 0 | D48: =-ROUND(IF($J$16="Sim",0,D47/30*($J$4+_xlfn.XLOOKUP($I$16,'Dados de apoio'!$A:$A,'Dados de apoio'!$B:$B))),0) -> 0 | E48: =-ROUND(IF($J$16="Sim",0,E47/30*($J$4+_xlfn.XLOOKUP($I$16,'Dados de apoio'!$A:$A,'Dados de apoio'!$B:$B))),0) -> 0 | F48: =SUM(B48:E48) -> 0
...

Sheet GBarbosa
A1: Gbarbosa | B1: Perecíves | C1: Mercearia | D1: Eletro | E1: Hipel | F1: Total | I1: Quant. Operadores Caixa | J1: 6 | M1: Caixa | N1: ='Dados de apoio'!B21 -> 700000
I2: Quant. Operadores Serviço | J2: 3 | M2: Estoque | N2: =-(F5+F23) -> -214600
A3: Qtd Estoque | B3: 900 | C3: 1500 | D3: 80 | E3: 1400 | F3: =SUM(B3:E3) -> 3880 | I3: Resultado Testes | J3: 0.7 | M3: CAPEX | N3: =-L20 -> -395000
A4: Custo Unit | B4: ='Dados de apoio'!H3 -> 20 | C4: ='Dados de apoio'!I3 -> 30 | D4: ='Dados de apoio'!J3 -> 500 | E4: ='Dados de apoio'!K3 -> 45 | I4: SLA Serviços | J4: =IF(J2="",6,IFERROR(_xlfn.XLOOKUP(J2,'Dados de apoio'!O:O,'Dados de apoio'!P:P),5)) -> 3 | M4: Saldo | N4: =SUM(N1:N3) -> 90400
A5: Total Estoque | B5: =B3*B4 -> 18000 | C5: =C3*C4 -> 45000 | D5: =D3*D4 -> 40000 | E5: =E3*E4 -> 63000 | F5: =SUM(B5:E5) -> 166000 | I5: CSAT | J5: =J3*(J1/'Dados de apoio'!R4) -> 0.42 | N5: =IF(N4<0,"Revisar Caixa","Caixa OK") -> Caixa OK
A7: MIX Disponível | B7: ='Dados de apoio'!H4 -> 4000 | C7: ='Dados de apoio'!I4 -> 6000 | D7: ='Dados de apoio'!J4 -> 700 | E7: ='Dados de apoio'!K4 -> 5000 | F7: =SUM(B7:E7) -> 15700
A8: Disponibilidade | B8: =B3/B7 -> 0.225 | C8: =C3/C7 -> 0.25 | D8: =D3/D7 -> 0.11428571 | E8: =E3/E7 -> 0.28 | F8: =F3/F7 -> 0.24713376
J9: 1ª Conf. | K9: 2ª Conf.
I10: Disponibiliidade | J10: =F8 -> 0.24713376 | K10: =F26 -> 0.34484076
A11: % Margem | B11: 0.14 | C11: 0.11 | D11: 0.3 | E11: 0.19 | I11: Preço da Cesta | J11: =SUM(B14:E14) -> 992.90028 | K11: =SUM(B31:E31) -> 985.63842
A12: % Impostos | B12: ='Dados de apoio'!H5 -> 0.12 | C12: ='Dados de apoio'!I5 -> 0.07 | D12: ='Dados de apoio'!J5 -> 0.25 | E12: ='Dados de apoio'!K5 -> 0.17
J13: Aprovado? | K13: Aprovado? | L13: R$
A14: Preço de Venda | B14: =(B4/(100%-B12))*(100%+B11) -> 25.909091 | C14: =(C4/(100%-C12))*(100%+C11) -> 35.806452 | D14: =(D4/(100%-D12))*(100%+D11) -> 866.66667 | E14: =(E4/(100%-E12))*(100%+E11) -> 64.518072 | I14: CAPEX Segurança | J14: Sim | K14: =J14 -> Sim | L14: =IF(K14="Sim",_xlfn.XLOOKUP(I14,'Dados de apoio'!A:A,'Dados de apoio'!C:C),0) -> 50000
I15: CAPEX Balança/Freezer | J15: Sim | K15: =J15 -> Sim | L15: =IF(K15="Sim",_xlfn.XLOOKUP(I15,'Dados de apoio'!A:A,'Dados de apoio'!C:C),0) -> 75000
I16: CAPEX Redes | J16: Sim | K16: =J16 -> Sim | L16: =IF(K16="Sim",_xlfn.XLOOKUP(I16,'Dados de apoio'!A:A,'Dados de apoio'!C:C),0) -> 80000
I17: CAPEX Site | J17: Sim | K17: =J17 -> Sim | L17: =IF(K17="Sim",_xlfn.XLOOKUP(I17,'Dados de apoio'!A:A,'Dados de apoio'!C:C),0) -> 65000
A18: --------------------------------- | I18: CAPEX Self Checkout | J18: Sim | K18: =J18 -> Sim | L18: =IF(K18="Sim",_xlfn.XLOOKUP(I18,'Dados de apoio'!A:A,'Dados de apoio'!C:C),0) -> 80000
A19: 2ª Rodada de configuração | I19: CAPEX Melhoria Contínua | J19: Sim | K19: =J19 -> Sim | L19: =IF(K19="Sim",_xlfn.XLOOKUP(I19,'Dados de apoio'!A:A,'Dados de apoio'!C:C),0) -> 45000
A20: Gbarbosa | B20: Perecíves | C20: Mercearia | D20: Eletro | E20: Hipel | F20: Total | J20: Total CAPEX | L20: =SUM(L14:L19) -> 395000
A21: Estoque Atual | B21: =B44 -> 486 | C21: =C44 -> 879 | D21: =D44 -> 8 | E21: =E44 -> 882 | F21: =SUM(B21:E21) -> 2255
A22: Qtd A comprar | B22: 90 | C22: 150 | D22: 72 | E22: 140 | F22: =SUM(B22:E22) -> 452
A23: R$ Total Comprado | B23: =B22*B4 -> 1800 | C23: =C22*C4 -> 4500 | D23: =D22*D4 -> 36000 | E23: =E22*E4 -> 6300 | F23: =SUM(B23:E23) -> 48600
A24: Novo Estoque | B24: =B21+B22 -> 576 | C24: =C21+C22 -> 1029 | D24: =D21+D22 -> 80 | E24: =E21+E22 -> 1022 | F24: =SUM(B24:E24) -> 2707 | I24: Licença Software | J24: QTd | K24: Valor CAPEX | L24: Valor CAPEX
I25: Sistema Operacional (por usuário) | J25: =J2 -> 3 | K25: ='Dados de apoio'!B12 -> 120 | L25: =K25*J25 -> 360
A26: Disponibilidade | B26: =B24/(B7-'Dados de apoio'!H13) -> 0.288 | C26: =C24/(C7-'Dados de apoio'!I13) -> 0.343 | D26: =D24/(D7-'Dados de apoio'!J13) -> 0.22857143 | E26: =E24/(E7-'Dados de apoio'!K13) -> 0.4088 | F26: =F24/(F7-'Dados de apoio'!L13) -> 0.34484076 | I26: PDVs + Selfcheckout (Por Equipamento) | J26: =J1+IF(J18="Sim",4,0) -> 10 | K26: ='Dados de apoio'!B13 -> 80 | L26: =K26*J26 -> 800
I27: Site (Valor único) | J27: 1 | K27: ='Dados de apoio'!B14*IF(K17="sim",1.3,1) -> 650 | L27: =K27*J27 -> 650
A28: % Margem | B28: 0.13 | C28: 0.06 | D28: 0.3 | E28: 0.09 | I28: Sistemas de segurança (Valor único) | J28: 1 | K28: ='Dados de apoio'!B15*IF(K14="sim",1.2,1) -> 600 | L28: =K28*J28 -> 600
A29: % Impostos | B29: ='Dados de apoio'!H5 -> 0.12 | C29: ='Dados de apoio'!I5 -> 0.07 | D29: ='Dados de apoio'!J5 -> 0.25 | E29: ='Dados de apoio'!K5 -> 0.17 | K29: Total | L29: =SUM(L25:L28) -> 2410
A31: Preço de Venda | B31: =(B4/(100%-B29))*(100%+B28) -> 25.681818 | C31: =(C4/(100%-C29))*(100%+C28) -> 34.193548 | D31: =(D4/(100%-D29))*(100%+D28) -> 866.66667 | E31: =(E4/(100%-E29))*(100%+E28) -> 59.096386
A35: 1ª Rodada de Vendas
A36: Rodada 1 | B36: =_xlfn.XLOOKUP($A36&$A$1,'Rodada 1 de Venda'!$G:$G,'Rodada 1 de Venda'!B:B) -> 414 | C36: =_xlfn.XLOOKUP($A36&$A1,'Rodada 1 de Venda'!$G:$G,'Rodada 1 de Venda'!C:C) -> 621 | D36: =_xlfn.XLOOKUP($A36&$A1,'Rodada 1 de Venda'!$G:$G,'Rodada 1 de Venda'!D:D) -> 72 | E36: =_xlfn.XLOOKUP($A36&$A1,'Rodada 1 de Venda'!$G:$G,'Rodada 1 de Venda'!E:E) -> 518 | F36: =SUM(B36:E36) -> 1625
A37: Incidente Segurança | B37: =-ROUND(IF($J$14="Sim",0,B36/30*($J$4+_xlfn.XLOOKUP($I$14,'Dados de apoio'!$A:$A,'Dados de apoio'!$B:$B))),0) -> 0 | C37: =-ROUND(IF($J$14="Sim",0,C36/30*($J$4+_xlfn.XLOOKUP($I$14,'Dados de apoio'!$A:$A,'Dados de apoio'!$B:$B))),0) -> 0 | D37: =-ROUND(IF($J$14="Sim",0,D36/30*($J$4+_xlfn.XLOOKUP($I$14,'Dados de apoio'!$A:$A,'Dados de apoio'!$B:$B))),0) -> 0 | E37: =-ROUND(IF($J$14="Sim",0,E36/30*($J$4+_xlfn.XLOOKUP($I$14,'Dados de apoio'!$A:$A,'Dados de apoio'!$B:$B))),0) -> 0 | F37: =SUM(B37:E37) -> 0
A38: Incidente Balanças/Freezer | B38: =-ROUND(IF($J$15="Sim",0,B36/30*($J$4+_xlfn.XLOOKUP($I$15,'Dados de apoio'!$A:$A,'Dados de apoio'!$B:$B))),0) -> 0 | C38: 0 | D38: 0 | E38: 0 | F38: =SUM(B38:E38) -> 0
A39: Devolução Venda | B39: =IF(SUM(B36:B38)>B3,B3-SUM(B36:B38),0) -> 0 | C39: =IF(SUM(C36:C38)>C3,C3-SUM(C36:C38),0) -> 0 | D39: =IF(SUM(D36:D38)>D3,D3-SUM(D36:D38),0) -> 0 | E39: =IF(SUM(E36:E38)>E3,E3-SUM(E36:E38),0) -> 0 | F39: =SUM(B39:E39) -> 0
A40: Total Vendido | B40: =SUM(B36:B39) -> 414 | C40: =SUM(C36:C39) -> 621 | D40: =SUM(D36:D39) -> 72 | E40: =SUM(E36:E39) -> 518 | F40: =SUM(F36:F39) -> 1625
A42: Valor de venda | B42: =B40*B$14 -> 10726.364 | C42: =C40*C$14 -> 22235.806 | D42: =D40*D$14 -> 62400 | E42: =E40*E$14 -> 33420.361 | F42: =SUM(B42:E42) -> 128782.53
A44: Estoque | B44: =B3-B40 -> 486 | C44: =C3-C40 -> 879 | D44: =D3-D40 -> 8 | E44: =E3-E40 -> 882
A46: 2ª Rodada de Vendas
A47: Rodada 2 | B47: =_xlfn.XLOOKUP($A47&$A$1,'Demais Rodadas de Venda'!$G:$G,'Demais Rodadas de Venda'!B:B) -> 175 | C47: =_xlfn.XLOOKUP($A47&$A$1,'Demais Rodadas de Venda'!$G:$G,'Demais Rodadas de Venda'!C:C) -> 263 | D47: =_xlfn.XLOOKUP($A47&$A$1,'Demais Rodadas de Venda'!$G:$G,'Demais Rodadas de Venda'!D:D) -> 31 | E47: =_xlfn.XLOOKUP($A47&$A$1,'Demais Rodadas de Venda'!$G:$G,'Demais Rodadas de Venda'!E:E) -> 219 | F47: =SUM(B47:E47) -> 688
A48: Incidente Cartões | B48: =-ROUND(IF($J$16="Sim",0,B47/30*($J$4+_xlfn.XLOOKUP($I$16,'Dados de apoio'!$A:$A,'Dados de apoio'!$B:$B))),0) -> 0 | C48: =-ROUND(IF($J$16="Sim",0,C47/30*($J$4+_xlfn.XLOOKUP($I$16,'Dados de apoio'!$A:$A,'Dados de apoio'!$B:$B))),0) -> 0 | D48: =-ROUND(IF($J$16="Sim",0,D47/30*($J$4+_xlfn.XLOOKUP($I$16,'Dados de apoio'!$A:$A,'Dados de apoio'!$B:$B))),0) -> 0 | E48: =-ROUND(IF($J$16="Sim",0,E47/30*($J$4+_xlfn.XLOOKUP($I$16,'Dados de apoio'!$A:$A,'Dados de apoio'!$B:$B))),0) -> 0 | F48: =SUM(B48:E48) -> 0
...

Sheet Prezunic
A1: Prezunic | B1: Perecíves | C1: Mercearia | D1: Eletro | E1: Hipel | F1: Total | I1: Quant. Operadores Caixa | J1: 10 | M1: Caixa | N1: ='Dados de apoio'!B21 -> 700000
I2: Quant. Operadores Serviço | J2: 4 | M2: Estoque | N2: =-(F5+F23) -> -305000
A3: Qtd Estoque | B3: 800 | C3: 1200 | D3: 140 | E3: 1000 | F3: =SUM(B3:E3) -> 3140 | I3: Resultado Testes | J3: 0.2 | M3: CAPEX | N3: =-L20 -> -395000
A4: Custo Unit | B4: ='Dados de apoio'!H3 -> 20 | C4: ='Dados de apoio'!I3 -> 30 | D4: ='Dados de apoio'!J3 -> 500 | E4: ='Dados de apoio'!K3 -> 45 | I4: SLA Serviços | J4: =IF(J2="",6,IFERROR(_xlfn.XLOOKUP(J2,'Dados de apoio'!O:O,'Dados de apoio'!P:P),5)) -> 2 | M4: Saldo | N4: =SUM(N1:N3) -> 0
A5: Total Estoque | B5: =B3*B4 -> 16000 | C5: =C3*C4 -> 36000 | D5: =D3*D4 -> 70000 | E5: =E3*E4 -> 45000 | F5: =SUM(B5:E5) -> 167000 | I5: CSAT | J5: =J3*(J1/'Dados de apoio'!R4) -> 0.2 | N5: =IF(N4<0,"Revisar Caixa","Caixa OK") -> Caixa OK
A7: MIX Disponível | B7: ='Dados de apoio'!H4 -> 4000 | C7: ='Dados de apoio'!I4 -> 6000 | D7: ='Dados de apoio'!J4 -> 700 | E7: ='Dados de apoio'!K4 -> 5000 | F7: =SUM(B7:E7) -> 15700
A8: Disponibilidade | B8: =B3/B7 -> 0.2 | C8: =C3/C7 -> 0.2 | D8: =D3/D7 -> 0.2 | E8: =E3/E7 -> 0.2 | F8: =F3/F7 -> 0.2
J9: 1ª Conf. | K9: 2ª Conf.
I10: Disponibiliidade | J10: =F8 -> 0.2 | K10: =F26 -> 0.58305732
A11: % Margem | B11: 0.2 | C11: 0.1 | D11: 0.3 | E11: 0.15 | I11: Preço da Cesta | J11: =SUM(B14:E14) -> 991.77266 | K11: =SUM(B31:E31) -> 855.72849
A12: % Impostos | B12: ='Dados de apoio'!H5 -> 0.12 | C12: ='Dados de apoio'!I5 -> 0.07 | D12: ='Dados de apoio'!J5 -> 0.25 | E12: ='Dados de apoio'!K5 -> 0.17
J13: Aprovado? | K13: Aprovado? | L13: R$
A14: Preço de Venda | B14: =(B4/(100%-B12))*(100%+B11) -> 27.272727 | C14: =(C4/(100%-C12))*(100%+C11) -> 35.483871 | D14: =(D4/(100%-D12))*(100%+D11) -> 866.66667 | E14: =(E4/(100%-E12))*(100%+E11) -> 62.349398 | I14: CAPEX Segurança | J14: Sim | K14: =J14 -> Sim | L14: =IF(K14="Sim",_xlfn.XLOOKUP(I14,'Dados de apoio'!A:A,'Dados de apoio'!C:C),0) -> 50000
I15: CAPEX Balança/Freezer | J15: Sim | K15: =J15 -> Sim | L15: =IF(K15="Sim",_xlfn.XLOOKUP(I15,'Dados de apoio'!A:A,'Dados de apoio'!C:C),0) -> 75000
I16: CAPEX Redes | J16: Sim | K16: =J16 -> Sim | L16: =IF(K16="Sim",_xlfn.XLOOKUP(I16,'Dados de apoio'!A:A,'Dados de apoio'!C:C),0) -> 80000
I17: CAPEX Site | J17: Sim | K17: =J17 -> Sim | L17: =IF(K17="Sim",_xlfn.XLOOKUP(I17,'Dados de apoio'!A:A,'Dados de apoio'!C:C),0) -> 65000
A18: --------------------------------- | I18: CAPEX Self Checkout | J18: Sim | K18: =J18 -> Sim | L18: =IF(K18="Sim",_xlfn.XLOOKUP(I18,'Dados de apoio'!A:A,'Dados de apoio'!C:C),0) -> 80000
A19: 2ª Rodada de configuração | I19: CAPEX Melhoria Contínua | J19: Sim | K19: =J19 -> Sim | L19: =IF(K19="Sim",_xlfn.XLOOKUP(I19,'Dados de apoio'!A:A,'Dados de apoio'!C:C),0) -> 45000
A20: Prezunic | B20: Perecíves | C20: Mercearia | D20: Eletro | E20: Hipel | F20: Total | J20: Total CAPEX | L20: =SUM(L14:L19) -> 395000
A21: Estoque Atual | B21: =B44 -> 524 | C21: =C44 -> 786 | D21: =D44 -> 92 | E21: =E44 -> 655 | F21: =SUM(B21:E21) -> 2057
A22: Qtd A comprar | B22: 600 | C22: 1000 | D22: 120 | E22: 800 | F22: =SUM(B22:E22) -> 2520
A23: R$ Total Comprado | B23: =B22*B4 -> 12000 | C23: =C22*C4 -> 30000 | D23: =D22*D4 -> 60000 | E23: =E22*E4 -> 36000 | F23: =SUM(B23:E23) -> 138000
A24: Novo Estoque | B24: =B21+B22 -> 1124 | C24: =C21+C22 -> 1786 | D24: =D21+D22 -> 212 | E24: =E21+E22 -> 1455 | F24: =SUM(B24:E24) -> 4577 | I24: Licença Software | J24: QTd | K24: Valor CAPEX | L24: Valor CAPEX
I25: Sistema Operacional (por usuário) | J25: =J2 -> 4 | K25: ='Dados de apoio'!B12 -> 120 | L25: =K25*J25 -> 480
A26: Disponibilidade | B26: =B24/(B7-'Dados de apoio'!H13) -> 0.562 | C26: =C24/(C7-'Dados de apoio'!I13) -> 0.59533333 | D26: =D24/(D7-'Dados de apoio'!J13) -> 0.60571429 | E26: =E24/(E7-'Dados de apoio'!K13) -> 0.582 | F26: =F24/(F7-'Dados de apoio'!L13) -> 0.58305732 | I26: PDVs + Selfcheckout (Por Equipamento) | J26: =J1+IF(J18="Sim",4,0) -> 14 | K26: ='Dados de apoio'!B13 -> 80 | L26: =K26*J26 -> 1120
I27: Site (Valor único) | J27: 1 | K27: ='Dados de apoio'!B14*IF(K17="sim",1.3,1) -> 650 | L27: =K27*J27 -> 650
A28: % Margem | B28: 0.2 | C28: 0.1 | D28: 0.1 | E28: 0.1 | I28: Sistemas de segurança (Valor único) | J28: 1 | K28: ='Dados de apoio'!B15*IF(K14="sim",1.2,1) -> 600 | L28: =K28*J28 -> 600
A29: % Impostos | B29: ='Dados de apoio'!H5 -> 0.12 | C29: ='Dados de apoio'!I5 -> 0.07 | D29: ='Dados de apoio'!J5 -> 0.25 | E29: ='Dados de apoio'!K5 -> 0.17 | K29: Total | L29: =SUM(L25:L28) -> 2850
A31: Preço de Venda | B31: =(B4/(100%-B29))*(100%+B28) -> 27.272727 | C31: =(C4/(100%-C29))*(100%+C28) -> 35.483871 | D31: =(D4/(100%-D29))*(100%+D28) -> 733.33333 | E31: =(E4/(100%-E29))*(100%+E28) -> 59.638554
A35: 1ª Rodada de Vendas
A36: Rodada 1 | B36: =_xlfn.XLOOKUP($A36&$A$1,'Rodada 1 de Venda'!$G:$G,'Rodada 1 de Venda'!B:B) -> 276 | C36: =_xlfn.XLOOKUP($A36&$A1,'Rodada 1 de Venda'!$G:$G,'Rodada 1 de Venda'!C:C) -> 414 | D36: =_xlfn.XLOOKUP($A36&$A1,'Rodada 1 de Venda'!$G:$G,'Rodada 1 de Venda'!D:D) -> 48 | E36: =_xlfn.XLOOKUP($A36&$A1,'Rodada 1 de Venda'!$G:$G,'Rodada 1 de Venda'!E:E) -> 345 | F36: =SUM(B36:E36) -> 1083
A37: Incidente Segurança | B37: =-ROUND(IF($J$14="Sim",0,B36/30*($J$4+_xlfn.XLOOKUP($I$14,'Dados de apoio'!$A:$A,'Dados de apoio'!$B:$B))),0) -> 0 | C37: =-ROUND(IF($J$14="Sim",0,C36/30*($J$4+_xlfn.XLOOKUP($I$14,'Dados de apoio'!$A:$A,'Dados de apoio'!$B:$B))),0) -> 0 | D37: =-ROUND(IF($J$14="Sim",0,D36/30*($J$4+_xlfn.XLOOKUP($I$14,'Dados de apoio'!$A:$A,'Dados de apoio'!$B:$B))),0) -> 0 | E37: =-ROUND(IF($J$14="Sim",0,E36/30*($J$4+_xlfn.XLOOKUP($I$14,'Dados de apoio'!$A:$A,'Dados de apoio'!$B:$B))),0) -> 0 | F37: =SUM(B37:E37) -> 0
A38: Incidente Balanças/Freezer | B38: =-ROUND(IF($J$15="Sim",0,B36/30*($J$4+_xlfn.XLOOKUP($I$15,'Dados de apoio'!$A:$A,'Dados de apoio'!$B:$B))),0) -> 0 | C38: 0 | D38: 0 | E38: 0 | F38: =SUM(B38:E38) -> 0
A39: Devolução Venda | B39: =IF(SUM(B36:B38)>B3,B3-SUM(B36:B38),0) -> 0 | C39: =IF(SUM(C36:C38)>C3,C3-SUM(C36:C38),0) -> 0 | D39: =IF(SUM(D36:D38)>D3,D3-SUM(D36:D38),0) -> 0 | E39: =IF(SUM(E36:E38)>E3,E3-SUM(E36:E38),0) -> 0 | F39: =SUM(B39:E39) -> 0
A40: Total Vendido | B40: =SUM(B36:B39) -> 276 | C40: =SUM(C36:C39) -> 414 | D40: =SUM(D36:D39) -> 48 | E40: =SUM(E36:E39) -> 345 | F40: =SUM(F36:F39) -> 1083
A42: Valor de venda | B42: =B40*B$14 -> 7527.2727 | C42: =C40*C$14 -> 14690.323 | D42: =D40*D$14 -> 41600 | E42: =E40*E$14 -> 21510.542 | F42: =SUM(B42:E42) -> 85328.137
A44: Estoque | B44: =B3-B40 -> 524 | C44: =C3-C40 -> 786 | D44: =D3-D40 -> 92 | E44: =E3-E40 -> 655
A46: 2ª Rodada de Vendas
A47: Rodada 2 | B47: =_xlfn.XLOOKUP($A47&$A$1,'Demais Rodadas de Venda'!$G:$G,'Demais Rodadas de Venda'!B:B) -> 225 | C47: =_xlfn.XLOOKUP($A47&$A$1,'Demais Rodadas de Venda'!$G:$G,'Demais Rodadas de Venda'!C:C) -> 337 | D47: =_xlfn.XLOOKUP($A47&$A$1,'Demais Rodadas de Venda'!$G:$G,'Demais Rodadas de Venda'!D:D) -> 39 | E47: =_xlfn.XLOOKUP($A47&$A$1,'Demais Rodadas de Venda'!$G:$G,'Demais Rodadas de Venda'!E:E) -> 281 | F47: =SUM(B47:E47) -> 882
A48: Incidente Cartões | B48: =-ROUND(IF($J$16="Sim",0,B47/30*($J$4+_xlfn.XLOOKUP($I$16,'Dados de apoio'!$A:$A,'Dados de apoio'!$B:$B))),0) -> 0 | C48: =-ROUND(IF($J$16="Sim",0,C47/30*($J$4+_xlfn.XLOOKUP($I$16,'Dados de apoio'!$A:$A,'Dados de apoio'!$B:$B))),0) -> 0 | D48: =-ROUND(IF($J$16="Sim",0,D47/30*($J$4+_xlfn.XLOOKUP($I$16,'Dados de apoio'!$A:$A,'Dados de apoio'!$B:$B))),0) -> 0 | E48: =-ROUND(IF($J$16="Sim",0,E47/30*($J$4+_xlfn.XLOOKUP($I$16,'Dados de apoio'!$A:$A,'Dados de apoio'!$B:$B))),0) -> 0 | F48: =SUM(B48:E48) -> 0
...

Sheet Giga
A1: Giga | B1: Perecíves | C1: Mercearia | D1: Eletro | E1: Hipel | F1: Total | I1: Quant. Operadores Caixa | J1: 5 | M1: Caixa | N1: ='Dados de apoio'!B21 -> 700000
I2: Quant. Operadores Serviço | J2: 3 | M2: Estoque | N2: =-(F5+F23) -> -258185
A3: Qtd Estoque | B3: 1055 | C3: 1575 | D3: 50 | E3: 1240 | F3: =SUM(B3:E3) -> 3920 | I3: Resultado Testes | J3: 0.6 | M3: CAPEX | N3: =-L20 -> -350000
A4: Custo Unit | B4: ='Dados de apoio'!H3 -> 20 | C4: ='Dados de apoio'!I3 -> 30 | D4: ='Dados de apoio'!J3 -> 500 | E4: ='Dados de apoio'!K3 -> 45 | I4: SLA Serviços | J4: =IF(J2="",6,IFERROR(_xlfn.XLOOKUP(J2,'Dados de apoio'!O:O,'Dados de apoio'!P:P),5)) -> 3 | M4: Saldo | N4: =SUM(N1:N3) -> 91815
A5: Total Estoque | B5: =B3*B4 -> 21100 | C5: =C3*C4 -> 47250 | D5: =D3*D4 -> 25000 | E5: =E3*E4 -> 55800 | F5: =SUM(B5:E5) -> 149150 | I5: CSAT | J5: =J3*(J1/'Dados de apoio'!R4) -> 0.3 | N5: =IF(N4<0,"Revisar Caixa","Caixa OK") -> Caixa OK
A7: MIX Disponível | B7: ='Dados de apoio'!H4 -> 4000 | C7: ='Dados de apoio'!I4 -> 6000 | D7: ='Dados de apoio'!J4 -> 700 | E7: ='Dados de apoio'!K4 -> 5000 | F7: =SUM(B7:E7) -> 15700
A8: Disponibilidade | B8: =B3/B7 -> 0.26375 | C8: =C3/C7 -> 0.2625 | D8: =D3/D7 -> 0.071428571 | E8: =E3/E7 -> 0.248 | F8: =F3/F7 -> 0.24968153
J9: 1ª Conf. | K9: 2ª Conf.
I10: Disponibiliidade | J10: =F8 -> 0.24968153 | K10: =F26 -> 0.43821656
A11: % Margem | B11: 0.05 | C11: 0.2 | D11: 0.25 | E11: 0.15 | I11: Preço da Cesta | J11: =SUM(B14:E14) -> 958.25604 | K11: =SUM(B31:E31) -> 924.92271
A12: % Impostos | B12: ='Dados de apoio'!H5 -> 0.12 | C12: ='Dados de apoio'!I5 -> 0.07 | D12: ='Dados de apoio'!J5 -> 0.25 | E12: ='Dados de apoio'!K5 -> 0.17
J13: Aprovado? | K13: Aprovado? | L13: R$
A14: Preço de Venda | B14: =(B4/(100%-B12))*(100%+B11) -> 23.863636 | C14: =(C4/(100%-C12))*(100%+C11) -> 38.709677 | D14: =(D4/(100%-D12))*(100%+D11) -> 833.33333 | E14: =(E4/(100%-E12))*(100%+E11) -> 62.349398 | I14: CAPEX Segurança | J14: Sim | K14: =J14 -> Sim | L14: =IF(K14="Sim",_xlfn.XLOOKUP(I14,'Dados de apoio'!A:A,'Dados de apoio'!C:C),0) -> 50000
I15: CAPEX Balança/Freezer | J15: Não | K15: Sim | L15: =IF(K15="Sim",_xlfn.XLOOKUP(I15,'Dados de apoio'!A:A,'Dados de apoio'!C:C),0) -> 75000
I16: CAPEX Redes | J16: Sim | K16: =J16 -> Sim | L16: =IF(K16="Sim",_xlfn.XLOOKUP(I16,'Dados de apoio'!A:A,'Dados de apoio'!C:C),0) -> 80000
I17: CAPEX Site | J17: Sim | K17: =J17 -> Sim | L17: =IF(K17="Sim",_xlfn.XLOOKUP(I17,'Dados de apoio'!A:A,'Dados de apoio'!C:C),0) -> 65000
A18: --------------------------------- | I18: CAPEX Self Checkout | J18: Sim | K18: =J18 -> Sim | L18: =IF(K18="Sim",_xlfn.XLOOKUP(I18,'Dados de apoio'!A:A,'Dados de apoio'!C:C),0) -> 80000
A19: 2ª Rodada de configuração | I19: CAPEX Melhoria Contínua | K19: =J19 -> 0 | L19: =IF(K19="Sim",_xlfn.XLOOKUP(I19,'Dados de apoio'!A:A,'Dados de apoio'!C:C),0) -> 0
A20: GIGA | B20: Perecíves | C20: Mercearia | D20: Eletro | E20: Hipel | F20: Total | J20: Total CAPEX | L20: =SUM(L14:L19) -> 350000
A21: Estoque Atual | B21: =B44 -> 637 | C21: =C44 -> 852 | D21: =D44 -> 0 | E21: =E44 -> 637 | F21: =SUM(B21:E21) -> 2126
A22: Qtd A comprar | B22: 163 | C22: 648 | D22: 140 | E22: 363 | F22: =SUM(B22:E22) -> 1314
A23: R$ Total Comprado | B23: =B22*B4 -> 3260 | C23: =C22*C4 -> 19440 | D23: =D22*D4 -> 70000 | E23: =E22*E4 -> 16335 | F23: =SUM(B23:E23) -> 109035
A24: Novo Estoque | B24: =B21+B22 -> 800 | C24: =C21+C22 -> 1500 | D24: =D21+D22 -> 140 | E24: =E21+E22 -> 1000 | F24: =SUM(B24:E24) -> 3440 | I24: Licença Software | J24: QTd | K24: Valor CAPEX | L24: Valor CAPEX
I25: Sistema Operacional (por usuário) | J25: =J2 -> 3 | K25: ='Dados de apoio'!B12 -> 120 | L25: =K25*J25 -> 360
A26: Disponibilidade | B26: =B24/(B7-'Dados de apoio'!H13) -> 0.4 | C26: =C24/(C7-'Dados de apoio'!I13) -> 0.5 | D26: =D24/(D7-'Dados de apoio'!J13) -> 0.4 | E26: =E24/(E7-'Dados de apoio'!K13) -> 0.4 | F26: =F24/(F7-'Dados de apoio'!L13) -> 0.43821656 | I26: PDVs + Selfcheckout (Por Equipamento) | J26: =J1+IF(J18="Sim",4,0) -> 9 | K26: ='Dados de apoio'!B13 -> 80 | L26: =K26*J26 -> 720
I27: Site (Valor único) | J27: 1 | K27: ='Dados de apoio'!B14*IF(K17="sim",1.3,1) -> 650 | L27: =K27*J27 -> 650
A28: % Margem | B28: 0.05 | C28: 0.2 | D28: 0.2 | E28: 0.15 | I28: Sistemas de segurança (Valor único) | J28: 1 | K28: ='Dados de apoio'!B15*IF(K14="sim",1.2,1) -> 600 | L28: =K28*J28 -> 600
A29: % Impostos | B29: ='Dados de apoio'!H5 -> 0.12 | C29: ='Dados de apoio'!I5 -> 0.07 | D29: ='Dados de apoio'!J5 -> 0.25 | E29: ='Dados de apoio'!K5 -> 0.17 | K29: Total | L29: =SUM(L25:L28) -> 2330
A31: Preço de Venda | B31: =(B4/(100%-B29))*(100%+B28) -> 23.863636 | C31: =(C4/(100%-C29))*(100%+C28) -> 38.709677 | D31: =(D4/(100%-D29))*(100%+D28) -> 800 | E31: =(E4/(100%-E29))*(100%+E28) -> 62.349398
A35: 1ª Rodada de Vendas
A36: Rodada 1 | B36: =_xlfn.XLOOKUP($A36&$A$1,'Rodada 1 de Venda'!$G:$G,'Rodada 1 de Venda'!B:B) -> 482 | C36: =_xlfn.XLOOKUP($A36&$A1,'Rodada 1 de Venda'!$G:$G,'Rodada 1 de Venda'!C:C) -> 723 | D36: =_xlfn.XLOOKUP($A36&$A1,'Rodada 1 de Venda'!$G:$G,'Rodada 1 de Venda'!D:D) -> 84 | E36: =_xlfn.XLOOKUP($A36&$A1,'Rodada 1 de Venda'!$G:$G,'Rodada 1 de Venda'!E:E) -> 603 | F36: =SUM(B36:E36) -> 1892
A37: Incidente Segurança | B37: =-ROUND(IF($J$14="Sim",0,B36/30*($J$4+_xlfn.XLOOKUP($I$14,'Dados de apoio'!$A:$A,'Dados de apoio'!$B:$B))),0) -> 0 | C37: =-ROUND(IF($J$14="Sim",0,C36/30*($J$4+_xlfn.XLOOKUP($I$14,'Dados de apoio'!$A:$A,'Dados de apoio'!$B:$B))),0) -> 0 | D37: =-ROUND(IF($J$14="Sim",0,D36/30*($J$4+_xlfn.XLOOKUP($I$14,'Dados de apoio'!$A:$A,'Dados de apoio'!$B:$B))),0) -> 0 | E37: =-ROUND(IF($J$14="Sim",0,E36/30*($J$4+_xlfn.XLOOKUP($I$14,'Dados de apoio'!$A:$A,'Dados de apoio'!$B:$B))),0) -> 0 | F37: =SUM(B37:E37) -> 0
A38: Incidente Balanças/Freezer | B38: =-ROUND(IF($J$15="Sim",0,B36/30*($J$4+_xlfn.XLOOKUP($I$15,'Dados de apoio'!$A:$A,'Dados de apoio'!$B:$B))),0) -> -64 | C38: 0 | D38: 0 | E38: 0 | F38: =SUM(B38:E38) -> -64
A39: Devolução Venda | B39: =IF(SUM(B36:B38)>B3,B3-SUM(B36:B38),0) -> 0 | C39: =IF(SUM(C36:C38)>C3,C3-SUM(C36:C38),0) -> 0 | D39: =IF(SUM(D36:D38)>D3,D3-SUM(D36:D38),0) -> -34 | E39: =IF(SUM(E36:E38)>E3,E3-SUM(E36:E38),0) -> 0 | F39: =SUM(B39:E39) -> -34
A40: Total Vendido | B40: =SUM(B36:B39) -> 418 | C40: =SUM(C36:C39) -> 723 | D40: =SUM(D36:D39) -> 50 | E40: =SUM(E36:E39) -> 603 | F40: =SUM(F36:F39) -> 1794
A42: Valor de venda | B42: =B40*B$14 -> 9975 | C42: =C40*C$14 -> 27987.097 | D42: =D40*D$14 -> 41666.667 | E42: =E40*E$14 -> 37596.687 | F42: =SUM(B42:E42) -> 117225.45
A44: Estoque | B44: =B3-B40 -> 637 | C44: =C3-C40 -> 852 | D44: =D3-D40 -> 0 | E44: =E3-E40 -> 637
A46: 2ª Rodada de Vendas
A47: Rodada 2 | B47: =_xlfn.XLOOKUP($A47&$A$1,'Demais Rodadas de Venda'!$G:$G,'Demais Rodadas de Venda'!B:B) -> 150 | C47: =_xlfn.XLOOKUP($A47&$A$1,'Demais Rodadas de Venda'!$G:$G,'Demais Rodadas de Venda'!C:C) -> 224 | D47: =_xlfn.XLOOKUP($A47&$A$1,'Demais Rodadas de Venda'!$G:$G,'Demais Rodadas de Venda'!D:D) -> 26 | E47: =_xlfn.XLOOKUP($A47&$A$1,'Demais Rodadas de Venda'!$G:$G,'Demais Rodadas de Venda'!E:E) -> 187 | F47: =SUM(B47:E47) -> 587
A48: Incidente Cartões | B48: =-ROUND(IF($J$16="Sim",0,B47/30*($J$4+_xlfn.XLOOKUP($I$16,'Dados de apoio'!$A:$A,'Dados de apoio'!$B:$B))),0) -> 0 | C48: =-ROUND(IF($J$16="Sim",0,C47/30*($J$4+_xlfn.XLOOKUP($I$16,'Dados de apoio'!$A:$A,'Dados de apoio'!$B:$B))),0) -> 0 | D48: =-ROUND(IF($J$16="Sim",0,D47/30*($J$4+_xlfn.XLOOKUP($I$16,'Dados de apoio'!$A:$A,'Dados de apoio'!$B:$B))),0) -> 0 | E48: =-ROUND(IF($J$16="Sim",0,E47/30*($J$4+_xlfn.XLOOKUP($I$16,'Dados de apoio'!$A:$A,'Dados de apoio'!$B:$B))),0) -> 0 | F48: =SUM(B48:E48) -> 0
...

Sheet Dados de apoio
A1: Capex | B1: Dias sem venda | C1: Valor CAPEX | H1: Perecíves | I1: Mercearia | J1: Eletro | K1: Hipel | L1: Total
A2: Capex Segurança | B2: 2 | C2: 50000 | O2: Profissional | P2: Custo Folha/Mês | R2: Qtd Ideal
A3: Capex Balança/Freezer | B3: 1 | C3: 75000 | G3: Custo Unit | H3: 20 | I3: 30 | J3: 500 | K3: 45 | O3: Operadores Serviço | P3: 1200 | R3: 5
A4: Capex Redes | B4: 2 | C4: 80000 | G4: MIX Disponível | H4: 4000 | I4: 6000 | J4: 700 | K4: 5000 | L4: =SUM(H4:K4) -> 15700 | O4: Operador de Caixa | P4: 1000 | R4: 10
A5: Capex Site | B5: 1 | C5: 65000 | G5: % Impostos | H5: 0.12 | I5: 0.07 | J5: 0.25 | K5: 0.17
A6: Capex Self Checkout | B6: 2 | C6: 80000 | G6: % Quebras | H6: 0.02 | I6: 0.015 | J6: 0 | K6: 0.01
A7: Capex Melhoria Contínua | B7: 0 | C7: 45000 | G7: % Aging | H7: =70%/12 -> 0.058333333 | I7: =10%/12 -> 0.0083333333 | J7: =16%/12 -> 0.013333333 | K7: =13%/12 -> 0.010833333
B8: Total CAPEX | C8: =SUM(C2:C7) -> 395000
G9: Total Estoque | H9: =H4*H3 -> 80000 | I9: =I4*I3 -> 180000 | J9: =J4*J3 -> 350000 | K9: =K4*K3 -> 225000 | L9: =SUM(H9:K9) -> 835000 | O9: Qtd Oper. Serviços | P9: SLA Serviços
O10: 0 | P10: 6
A11: Licença Software | B11: Valor CAPEX | F11: Vendas | O11: 1 | P11: 5
A12: Sistema Operacional (por usuário) | B12: 120 | F12: % Venda | G12: Rodada | H12: Perecíves | I12: Mercearia | J12: Eletro | K12: Hipel | L12: Total | O12: 2 | P12: 4
A13: PDVs + Selfcheckout (Por Equipamento) | B13: 80 | E13: 0.5 | F13: 0.5 | G13: Rodada 1 | H13: =H$4*$F13 -> 2000 | I13: =I$4*$F13 -> 3000 | J13: =J$4*$F13 -> 350 | K13: =K$4*$F13 -> 2500 | L13: =SUM(H13:K13) -> 7850 | O13: 3 | P13: 3
A14: Site (Valor único) | B14: 500 | E14: 0.2 | F14: 0.2 | G14: Rodada 2 | H14: =H$4*$F14 -> 800 | I14: =I$4*$F14 -> 1200 | J14: =J$4*$F14 -> 140 | K14: =K$4*$F14 -> 1000 | L14: =SUM(H14:K14) -> 3140 | O14: 4 | P14: 2
A15: Sistemas de segurança (Valor único) | B15: 500 | E15: 0.3 | F15: 0.3 | G15: Rodada 3 | H15: =H$4*$F15 -> 1200 | I15: =I$4*$F15 -> 1800 | J15: =J$4*$F15 -> 210 | K15: =K$4*$F15 -> 1500 | L15: =SUM(H15:K15) -> 4710 | O15: 5 | P15: 1
A16: Total | B16: =SUM(B12:B15) -> 1200 | F16: =SUM(F13:F15) -> 1 | G16: Total | H16: =SUM(H13:H15) -> 4000 | I16: =SUM(I13:I15) -> 6000 | J16: =SUM(J13:J15) -> 700 | K16: =SUM(K13:K15) -> 5000 | L16: =SUM(L13:L15) -> 15700
F19: 0.1 | G19: Rodada Atacado | H19: =H$4*$F19 -> 400 | I19: =I$4*$F19 -> 600 | J19: =J$4*$F19 -> 70 | K19: =K$4*$F19 -> 500 | L19: =SUM(H19:K19) -> 1570
O20: Gabarito prova conhecimento
A21: Total Caixa R$ | B21: 700000 | O21: 1 - C
O22: 2 - C
A23: Taxa Empréstimo (Mensal) | B23: 0.12 | O23: 3 - C
O24: 4 - A
A25: Manutenção Equipamentos | B25: 400 | O25: 5 - A
O26: 6 - D
O27: 7 - B
O28: 8 - D
O29: 9 - C
O30: 10 - A

Sheet Resumo
C1: Bretas | E1: GBarbosa | G1: Prezunic | I1: Giga
B2: CAIXA R$
B3: CAIXA R$ | C3: ='Dados de apoio'!B21 -> 700000 | E3: ='Dados de apoio'!B21 -> 700000 | G3: =E3 -> 700000 | I3: =G3 -> 700000
B4: (-) Estoque R$ | C4: =Bretas!N2 -> -334120 | E4: =GBarbosa!N2 -> -214600 | G4: =Prezunic!N2 -> -305000 | I4: =Giga!N2 -> -258185
B5: (-) CAPEX R$ | C5: =Bretas!N3 -> -320000 | E5: =GBarbosa!N3 -> -395000 | G5: =Prezunic!N3 -> -395000 | I5: =Giga!N3 -> -350000
B6: Saldo Caixa | C6: =SUM(C3:C5) -> 45880 | E6: =SUM(E3:E5) -> 90400 | G6: =SUM(G3:G5) -> 0 | I6: =SUM(I3:I5) -> 91815
B8: 1ª Configuração
B9: Disponibilidade % | C9: =Bretas!J10 -> 0.25 | E9: =GBarbosa!J10 -> 0.24713376 | G9: =Prezunic!J10 -> 0.2 | I9: =Giga!J10 -> 0.24968153
B10: Preço Médio Cesta R$ | C10: =Bretas!J11 -> 868.97314 | E10: =GBarbosa!J11 -> 992.90028 | G10: =Prezunic!J11 -> 991.77266 | I10: =Giga!J11 -> 958.25604
B11: CSAT % | C11: =Bretas!J5 -> 0.8 | E11: =GBarbosa!J5 -> 0.42 | G11: =Prezunic!J5 -> 0.2 | I11: =Giga!J5 -> 0.3
B12: % Participação nas Vendas | C12: ='Rodada 1 de Venda'!E2 -> 0.414 | E12: ='Rodada 1 de Venda'!E3 -> 0.207 | G12: ='Rodada 1 de Venda'!E4 -> 0.138 | I12: ='Rodada 1 de Venda'!E5 -> 0.241
B14: 2ª Configuração
B15: Disponibilidade % | C15: =Bretas!K10 -> 0.37452229 | E15: =GBarbosa!K10 -> 0.34484076 | G15: =Prezunic!K10 -> 0.58305732 | I15: =Giga!K10 -> 0.43821656
B16: Preço Médio Cesta R$ | C16: =Bretas!K11 -> 899.91641 | E16: =GBarbosa!K11 -> 985.63842 | G16: =Prezunic!K11 -> 855.72849 | I16: =Giga!K11 -> 924.92271
B17: CSAT % | C17: =C11 -> 0.8 | E17: =E11 -> 0.42 | G17: =G11 -> 0.2 | I17: =I11 -> 0.3
B18: % Participação nas Vendas | C18: ='Demais Rodadas de Venda'!E2 -> 0.313 | E18: ='Demais Rodadas de Venda'!E3 -> 0.219 | G18: ='Demais Rodadas de Venda'!E4 -> 0.281 | I18: ='Demais Rodadas de Venda'!E5 -> 0.188
B20: 1ª Rodada de Vendas
B21: Quant. Direcionada para Loja | C21: =Bretas!F36 -> 3250 | E21: =GBarbosa!F36 -> 1625 | G21: =Prezunic!F36 -> 1083 | I21: =Giga!F36 -> 1892
B22: Incidente Segurança | C22: =Bretas!F37 -> 0 | E22: =GBarbosa!F37 -> 0 | G22: =Prezunic!F37 -> 0 | I22: =Giga!F37 -> 0
B23: Incidente Balanças/Freezer | C23: =Bretas!F38 -> -55 | E23: =GBarbosa!F38 -> 0 | G23: =Prezunic!F38 -> 0 | I23: =Giga!F38 -> -64
B24: Devolução Venda | C24: =Bretas!F39 -> 0 | E24: =GBarbosa!F39 -> 0 | G24: =Prezunic!F39 -> 0 | I24: =Giga!F39 -> -34
B25: Total Vendido | C25: =SUM(C21:D24) -> 3195 | E25: =SUM(E21:F24) -> 1625 | G25: =SUM(G21:H24) -> 1083 | I25: =SUM(I21:J24) -> 1794
B27: Valor de venda | C27: =Bretas!F42 -> 235663.48 | E27: =GBarbosa!F42 -> 128782.53 | G27: =Prezunic!F42 -> 85328.137 | I27: =Giga!F42 -> 117225.45
B29: 2ª Rodada de Vendas
B30: Quant. Direcionada para Loja | C30: =Bretas!F47 -> 983 | E30: =GBarbosa!F47 -> 688 | G30: =Prezunic!F47 -> 882 | I30: =Giga!F47 -> 587
B31: Incidente Cartões | C31: =Bretas!F48 -> 0 | E31: =GBarbosa!F48 -> 0 | G31: =Prezunic!F48 -> 0 | I31: =Giga!F48 -> 0
B32: Incidente site | C32: =Bretas!F49 -> 0 | E32: =GBarbosa!F49 -> 0 | G32: =Prezunic!F49 -> 0 | I32: =Giga!F49 -> 0
B33: Devolução Venda | C33: =Bretas!F50 -> 0 | E33: =GBarbosa!F50 -> 0 | G33: =Prezunic!F50 -> 0 | I33: =Giga!F50 -> 0
B34: Total Vendido | C34: =SUM(C30:D33) -> 983 | E34: =SUM(E30:F33) -> 688 | G34: =SUM(G30:H33) -> 882 | I34: =SUM(I30:J33) -> 587
B36: Valor de venda | C36: =Bretas!F53 -> 76191.053 | E36: =GBarbosa!F53 -> 53295.997 | G36: =Prezunic!F53 -> 63452.862 | I36: =Giga!F53 -> 44709.851
B38: Venda Atacado
B39: Quantidade da Venda | C39: =Bretas!F56 -> 320 | E39: =GBarbosa!F56 -> 900 | G39: =Prezunic!F56 -> 0 | I39: =Giga!F56 -> 670
B40: Devolução Venda | C40: =Bretas!F57 -> 0 | E40: =GBarbosa!F57 -> 0 | G40: =Prezunic!F57 -> 0 | I40: =Giga!F57 -> 0
B41: Total Vendido | C41: =SUM(C39:D40) -> 320 | E41: =SUM(E39:F40) -> 900 | G41: =SUM(G39:H40) -> 0 | I41: =SUM(I39:J40) -> 670
B43: Valor de venda | C43: =Bretas!F60 -> 3200 | E43: =GBarbosa!F60 -> 18000 | G43: =Prezunic!F60 -> 0 | I43: =Giga!F60 -> 53600
B45: 3ª Rodada de Vendas
B46: Quant. Direcionada para Loja | C46: =Bretas!F67 -> 1475 | E46: =GBarbosa!F67 -> 1032 | G46: =Prezunic!F67 -> 1324 | I46: =Giga!F67 -> 879
B47: Alto fluxo de Clientes | C47: =Bretas!F68 -> 0 | E47: =GBarbosa!F68 -> 0 | G47: =Prezunic!F68 -> 0 | I47: =Giga!F68 -> 0
B48: Devolução Venda | C48: =Bretas!F69 -> -319 | E48: =GBarbosa!F69 -> -54 | G48: =Prezunic!F69 -> 0 | I48: =Giga!F69 -> 0
B49: Total Vendido | C49: =SUM(C46:D48) -> 1156 | E49: =SUM(E46:F48) -> 978 | G49: =SUM(G46:H48) -> 1324 | I49: =SUM(I46:J48) -> 879
...

Sheet Dados para o Word
F3: CAPEX | G3: Dias sem venda | H3: Valor CAPEX | M3: Qtd Oper. Serviços | N3: SLA Serviços
F4: CAPEX Segurança | G4: 2 + SLA | H4: 50000 | M4: 0 | N4: 6
F5: CAPEX Balança/Freezer | G5: 1 + SLA | H5: 75000 | M5: 1 | N5: 5
F6: CAPEX Redes | G6: 2 + SLA | H6: 80000 | M6: 2 | N6: 4
F7: CAPEX Site | G7: 1 + SLA | H7: 65000 | M7: 3 | N7: 3
F8: CAPEX Self Checkout | G8: 2 + SLA | H8: 80000 | M8: 4 | N8: 2
F9: CAPEX Melhoria Contínua | G9: 0 | H9: 45000 | M9: 5 | N9: 1
G10: Total CAPEX | H10: =SUM(H4:H9) -> 395000
B15: Licença Software | C15: Valor CAPEX | F15: Dados em UN | G15: Perecíves | H15: Mercearia | I15: Eletro | J15: Hipel | K15: Total | M15: Loja | N15: Preço Cesta | O15: Disponibilidade | P15: CSAT
B16: Sistema Operacional (por usuário) | C16: 120 | M16: Bretas | N16: 894.94538 | O16: 0.83872611 | P16: 1
B17: PDVs + Selfcheckout (Por Equipamento) | C17: 80 | F17: Estoque Disponível | G17: 1000 | H17: 1000 | I17: 1000 | J17: 1000 | K17: =SUM(G17:J17) -> 4000 | M17: GBarbosa | N17: 895.91312 | O17: 0.52299363 | P17: 0.7
B18: Site (Valor único) | C18: 500 | M18: Prezunic | N18: 871.07441 | O18: 0.44796178 | P18: 0.9
B19: Sistemas de segurança (Valor único) | C19: 500 | F19: Etoque comprado | G19: 670 | H19: 500 | I19: 800 | J19: 750 | K19: =SUM(G19:J19) -> 2720 | M19: Giga | N19: 894.30022 | O19: 0.55923567 | P19: 0.81
F21: Disponibilidade | G21: =G19/G17 -> 0.67 | H21: =H19/H17 -> 0.5 | I21: =I19/I17 -> 0.8 | J21: =J19/J17 -> 0.75 | K21: =K19/K17 -> 0.68
M22: Loja | N22: Preço Cesta | O22: Disponibilidade | P22: CSAT | Q22: Pontução | R22: % Demanda
M23: Bretas | N23: 1 | O23: 4 | P23: 4 | Q23: =SUM(N23:P23) -> 9 | R23: =Q23/$Q$27 -> 0.3
M24: GBarbosa | N24: 3 | O24: 2 | P24: 1 | Q24: =SUM(N24:P24) -> 6 | R24: =Q24/$Q$27 -> 0.2
G25: Perecíves | H25: Mercearia | I25: Eletro | J25: Hipel | M25: Prezunic | N25: 4 | O25: 1 | P25: 3 | Q25: =SUM(N25:P25) -> 8 | R25: =Q25/$Q$27 -> 0.26666667
M26: Giga | N26: 2 | O26: 3 | P26: 2 | Q26: =SUM(N26:P26) -> 7 | R26: =Q26/$Q$27 -> 0.23333333
F27: Custo | G27: ='Dados de apoio'!H3 -> 20 | H27: ='Dados de apoio'!I3 -> 30 | I27: ='Dados de apoio'!J3 -> 500 | J27: ='Dados de apoio'!K3 -> 45 | P27: Total | Q27: =SUM(Q23:Q26) -> 30 | R27: =SUM(R23:R26) -> 1
G30: Perecíves | H30: Mercearia | I30: Eletro | J30: Hipel | K30: Total
F31: Estoque Disponível | G31: 4000 | H31: 6000 | I31: 700 | J31: 5000 | K31: =SUM(G31:J31) -> 15700
G34: Perecíves | H34: Mercearia | I34: Eletro | J34: Hipel | K34: Total
F35: Vendas esperada (QTD) | G35: 4000 | H35: 6000 | I35: 700 | J35: 5000 | K35: =SUM(G35:J35) -> 15700
G38: Perecíves | H38: Mercearia | I38: Eletro | J38: Hipel
F39: % Impostos | G39: 0.12 | H39: 0.07 | I39: 0.25 | J39: 0.17
G42: Perecíves | H42: Mercearia | I42: Eletro | J42: Hipel
F43: % Quebras | G43: 0.02 | H43: 0.015 | I43: 0 | J43: 0.01
F44: % Aging | G44: =70%/12 -> 0.058333333 | H44: =10%/12 -> 0.0083333333 | I44: =16%/12 -> 0.013333333 | J44: =13%/12 -> 0.010833333
